<?xml version="1.0" encoding="utf-8"?>
<robot name="tbot" xmlns:xacro="http://www.ros.org/wiki/xacro">
<material name="black">
<color rgba="0.0 0.0 0.0 1.0"/>
</material>
<material name="white">
<color rgba="1.0 1.0 1.0 1.0"/>
</material>
<material name="darkgrey">
<color rgba="0.1 0.1 0.1 1.0"/>
</material>
<material name="grey">
<color rgba="0.3 0.3 0.3 1.0"/>
</material>
<material name="midgrey">
<color rgba="0.5 0.5 0.5 1.0"/>
</material>
<material name="lightgrey">
<color rgba="0.8 0.8 0.8 1.0"/>
</material>
<material name="blue">
<color rgba="0.2 0.2 0.8 1.0"/>
</material>
<material name="green">
<color rgba="0.0 0.8 0.0 1.0"/>
</material>
<material name="red">
<color rgba="0.8 0.1 0.1 1.0"/>
</material>
<material name="yellow">
<color rgba="0.8 0.8 0.0 1.0"/>
</material>
<material name="orange">
<color rgba="0.9 0.4 0.0 1.0"/>
</material>
<material name="brown">
<color rgba="0.9 0.8 0.7 1.0"/>
</material>
<link name="body">
<inertial>
<mass value="3.0"/>
<origin rpy="0 0 0" xyz="0 0 0.125"/>
<inertia ixx="0.02882" ixy="0.0" ixz="0.0" iyy="0.02882" iyz="0.0" izz="0.045"/>
</inertial>
<visual>
<origin rpy="0 0 0" xyz="0 0 0.164"/>
<geometry>
<box size="0.3 0.3 0.1"/>
</geometry>
<material name="orange"/>
</visual>
<collision>
<origin rpy="0 0 0" xyz="0 0 0.164"/>
<geometry>
<box size="0.3 0.3 0.1"/>
</geometry>
</collision>
</link>
<link name="motors_fused">
<visual>
<origin rpy="0 0 0" xyz="0 0 -0.04"/>
<geometry>
<box size="0.22 0.212 0.08"/>
</geometry>
<material name="grey"/>
</visual>
</link>
<link name="board">
<visual>
<origin rpy="0 0 0" xyz="0 0 0.035"/>
<geometry>
<box size="0.12 0.26 0.07"/>
</geometry>
<material name="lightgrey"/>
</visual>
</link>
<link name="sensor">
<visual>
<origin rpy="0 0 0" xyz="0.01 0 0"/>
<geometry>
<box size="0.02 0.06 0.06"/>
</geometry>
<material name="midgrey"/>
</visual>
</link>
<link name="wheel_1_left">
<inertial>
<mass value="0.75"/>
<origin rpy="1.57079632675 0 0" xyz="0 0.02 0.0"/>
<inertia ixx="0.000667" ixy="0.0" ixz="0.0" iyy="0.000667" iyz="0.0" izz="0.001134"/>
</inertial>
<visual>
<origin rpy="1.57079632675 0 0" xyz="0 0.02 0.0"/>
<geometry>
<cylinder radius="0.055" length="0.04"/>
</geometry>
<material name="lightgrey"/>
</visual>
<collision>
<origin rpy="1.57079632675 0 0" xyz="0 0.02 0.0"/>
<geometry>
<cylinder radius="0.055" length="0.04" />
</geometry>
</collision>
</link>
<link name="wheel_2_right">
<inertial>
<mass value="0.75"/>
<origin rpy="1.57079632675 0 0" xyz="0 -0.02 0.0"/>
<inertia ixx="0.000667" ixy="0.0" ixz="0.0" iyy="0.000667" iyz="0.0" izz="0.001134"/>
</inertial>
<visual>
<origin rpy="1.57079632675 0 0" xyz="0 -0.02 0.0"/>
<geometry>
<cylinder radius="0.055" length="0.04"/>
</geometry>
<material name="lightgrey"/>
</visual>
<collision>
<origin rpy="1.57079632675 0 0" xyz="0 -0.02 0.0"/>
<geometry>
<cylinder radius="0.055" length="0.04"/>
</geometry>
</collision>
</link>
<link name="wheel_3_left">
<inertial>
<mass value="0.75"/>
<origin rpy="1.57079632675 0 0" xyz="0 0.02 0.0"/>
<inertia ixx="0.000667" ixy="0.0" ixz="0.0" iyy="0.000667" iyz="0.0" izz="0.001134"/>
</inertial>
<visual>
<origin rpy="1.57079632675 0 0" xyz="0 0.02 0.0"/>
<geometry>
<cylinder radius="0.055" length="0.04"/>
</geometry>
<material name="lightgrey"/>
</visual>
<collision>
<origin rpy="1.57079632675 0 0" xyz="0 0.02 0.0"/>
<geometry>
<cylinder radius="0.055" length="0.04"/>
</geometry>
</collision>
</link>
<link name="wheel_4_right">
<inertial>
<mass value="0.75"/>
<origin rpy="1.57079632675 0 0" xyz="0 -0.02 0.0"/>
<inertia ixx="0.000667" ixy="0.0" ixz="0.0" iyy="0.000667" iyz="0.0" izz="0.001134"/>
</inertial>
<visual>
<origin rpy="1.57079632675 0 0" xyz="0 -0.02 0.0"/>
<geometry>
<cylinder radius="0.055" length="0.04"/>
</geometry>
<material name="lightgrey"/>
</visual>
<collision>
<origin rpy="1.57079632675 0 0" xyz="0 -0.02 0.0"/>
<geometry>
<cylinder radius="0.055" length="0.04"/>
</geometry>
</collision>
</link>
<link name="rotdot_1_left">
<visual>
<origin rpy="1.57079632675 0 0" xyz="0 0.002 0"/>
<geometry>
<box size="0.011 0.011 0.004"/>
</geometry>
<material name="midgrey"/>
</visual>
</link>
<link name="rotdot_2_right">
<visual>
<origin rpy="1.57079632675 0 0" xyz="0 -0.002 0"/>
<geometry>
<box size="0.011 0.011 0.004"/>
</geometry>
<material name="midgrey"/>
</visual>
</link>
<link name="rotdot_3_left">
<visual>
<origin rpy="1.57079632675 0 0" xyz="0 0.002 0"/>
<geometry>
<box size="0.011 0.011 0.004"/>
</geometry>
<material name="midgrey"/>
</visual>
</link>
<link name="rotdot_4_right">
<visual>
<origin rpy="1.57079632675 0 0" xyz="0 -0.002 0"/>
<geometry>
<box size="0.011 0.011 0.004"/>
</geometry>
<material name="midgrey"/>
</visual>
</link>
<joint name="body_motors_glue" type="fixed">
<parent link="body"/>
<child link="motors_fused"/>
<origin xyz="0.0 0.0 0.114"/>
</joint>
<joint name="body_board_glue" type="fixed">
<parent link="body"/>
<child link="board"/>
<origin xyz="0.066 0 0.214"/>
</joint>
<joint name="board_sensor_glue" type="fixed">
<parent link="board"/>
<child link="sensor"/>
<origin xyz="0.06 0 0.03"/>
</joint>
<joint name="wheel_rotdot_1_glue" type="fixed">
<parent link="wheel_1_left"/>
<child link="rotdot_1_left"/>
<origin xyz="0 0.04 0"/>
</joint>
<joint name="wheel_rotdot_2_glue" type="fixed">
<parent link="wheel_2_right"/>
<child link="rotdot_2_right"/>
<origin xyz="0 -0.04 0"/>
</joint>
<joint name="wheel_rotdot_3_glue" type="fixed">
<parent link="wheel_3_left"/>
<child link="rotdot_3_left"/>
<origin xyz="0 0.04 0"/>
</joint>
<joint name="wheel_rotdot_4_glue" type="fixed">
<parent link="wheel_4_right"/>
<child link="rotdot_4_right"/>
<origin xyz="0 -0.04 0"/>
</joint>
<joint name="wheel_1_axis" type="continuous">
<parent link="body"/>
<child link="wheel_1_left"/>
<origin xyz="0.08 0.106 0.055" rpy="0 0 0" />
<axis xyz="0 1 0" rpy="0 0 0" />
<dynamics damping="0.0" friction="0.0" />
</joint>
<joint name="wheel_2_axis" type="continuous">
<parent link="body"/>
<child link="wheel_2_right"/>
<origin xyz="0.08 -0.106 0.055" rpy="0 0 0" />
<axis xyz="0 1 0" rpy="0 0 0" />
<dynamics damping="0.0" friction="0.0" />
</joint>
<joint name="wheel_3_axis" type="continuous">
<parent link="body"/>
<child link="wheel_3_left"/>
<origin xyz="-0.08 0.106 0.055" rpy="0 0 0" />
<axis xyz="0 1 0" rpy="0 0 0" />
<dynamics damping="0.0" friction="0.0" />
</joint>
<joint name="wheel_4_axis" type="continuous">
<parent link="body"/>
<child link="wheel_4_right"/>
<origin xyz="-0.08 -0.106 0.055" rpy="0 0 0" />
<axis xyz="0 1 0" rpy="0 0 0" />
<dynamics damping="0.0" friction="0.0" />
</joint>
</robot>
