<?xml version="1.0"?>
<robot name="bot">
<link name="body">
    <inertial>
        <mass value="3.0"/>
        <origin rpy="0 0 0" xyz="0 0 0.125"/>
        <inertia ixx="0.02882" ixy="0.0" ixz="0.0" iyy="0.02882" iyz="0.0" izz="0.045"/>
    </inertial>
    <visual>
        <origin rpy="-1.57079632675 0 0" xyz="0 0 0.164"/>
        <geometry>
            <mesh filename="bot/cube.obj" scale="0.15 0.05 0.15"/>
        </geometry>
    </visual>
    <collision>
        <origin rpy="0 0 0" xyz="0 0 0.164"/>
        <geometry>
            <box size="0.3 0.3 0.1"/>
        </geometry>
    </collision>
</link>
<link name="motors_fused">
    <visual>
        <origin rpy="-1.57079632675 0 0" xyz="0 0 -0.04"/>
        <geometry>
            <mesh filename="bot/cube.obj" scale="0.11 0.04 0.106"/>
        </geometry>
    </visual>
</link>
<link name="board">
    <visual>
        <origin rpy="-1.57079632675 0 0" xyz="0 0 0.035"/>
        <geometry>
            <mesh filename="bot/cube.obj" scale="0.06 0.035 0.13"/>
        </geometry>
    </visual>
</link>
<link name="sensor">
    <visual>
        <origin rpy="-1.57079632675 0 0" xyz="0.01 0 0"/>
        <geometry>
            <mesh filename="bot/cube.obj" scale="0.01 0.03 0.045"/>
        </geometry>
    </visual>
</link>
<link name="wheel_1_left">
    <inertial>
        <mass value="0.75"/>
        <origin rpy="1.57079632675 0 0" xyz="0 0.02 0.0"/>
        <inertia ixx="0.000667" ixy="0.0" ixz="0.0" iyy="0.000667" iyz="0.0" izz="0.001134"/>
    </inertial>
    <visual>
        <origin rpy="0 0 0" xyz="0 0.02 0"/>
        <geometry>
            <mesh filename="bot/cylinder.obj" scale="0.055 0.04 0.055"/>
        </geometry>
    </visual>
    <collision>
        <origin rpy="1.57079632675 0 0" xyz="0 0.02 0.0"/>
        <geometry>
            <cylinder radius="0.055" length="0.04" />
        </geometry>
    </collision>
</link>
<link name="wheel_2_right">
    <inertial>
        <mass value="0.75"/>
        <origin rpy="1.57079632675 0 0" xyz="0 -0.02 0.0"/>
        <inertia ixx="0.000667" ixy="0.0" ixz="0.0" iyy="0.000667" iyz="0.0" izz="0.001134"/>
    </inertial>
    <visual>
        <origin rpy="0 0 0" xyz="0 -0.02 0"/>
        <geometry>
            <mesh filename="bot/cylinder.obj" scale="0.055 0.04 0.055"/>
        </geometry>
    </visual>
    <collision>
        <origin rpy="1.57079632675 0 0" xyz="0 -0.02 0.0"/>
        <geometry>
            <cylinder radius="0.055" length="0.04"/>
        </geometry>
    </collision>
</link>
<link name="wheel_3_left">
    <inertial>
        <mass value="0.75"/>
        <origin rpy="1.57079632675 0 0" xyz="0 0.02 0.0"/>
        <inertia ixx="0.000667" ixy="0.0" ixz="0.0" iyy="0.000667" iyz="0.0" izz="0.001134"/>
    </inertial>
    <visual>
        <origin rpy="0 0 0" xyz="0 0.02 0"/>
        <geometry>
            <mesh filename="bot/cylinder.obj" scale="0.055 0.04 0.055"/>
        </geometry>
    </visual>
    <collision>
        <origin rpy="1.57079632675 0 0" xyz="0 0.02 0.0"/>
        <geometry>
            <cylinder radius="0.055" length="0.04"/>
        </geometry>
    </collision>
</link>
<link name="wheel_4_right">
    <inertial>
        <mass value="0.75"/>
        <origin rpy="1.57079632675 0 0" xyz="0 -0.02 0.0"/>
        <inertia ixx="0.000667" ixy="0.0" ixz="0.0" iyy="0.000667" iyz="0.0" izz="0.001134"/>
    </inertial>
    <visual>
        <origin rpy="0 0 0" xyz="0 -0.02 0"/>
        <geometry>
            <mesh filename="bot/cylinder.obj" scale="0.055 0.04 0.055"/>
        </geometry>
    </visual>
    <collision>
        <origin rpy="1.57079632675 0 0" xyz="0 -0.02 0.0"/>
        <geometry>
            <cylinder radius="0.055" length="0.04"/>
        </geometry>
    </collision>
</link>
<joint name="body_motors_glue" type="fixed">
    <parent link="body"/>
    <child link="motors_fused"/>
    <origin xyz="0.0 0.0 0.114"/>
</joint>
<joint name="body_board_glue" type="fixed">
    <parent link="body"/>
    <child link="board"/>
    <origin xyz="0.066 0 0.214"/>
</joint>
<joint name="board_sensor_glue" type="fixed">
    <parent link="board"/>
    <child link="sensor"/>
    <origin xyz="0.06 0 0.03"/>
</joint>
<joint name="wheel_1_axis" type="continuous">
    <parent link="body"/>
    <child link="wheel_1_left"/>
    <origin xyz="0.08 0.106 0.055" rpy="0 0 0" />
    <axis xyz="0 1 0" rpy="0 0 0" />
    <dynamics damping="0.0" friction="0.0" />
</joint>
<joint name="wheel_2_axis" type="continuous">
    <parent link="body"/>
    <child link="wheel_2_right"/>
    <origin xyz="0.08 -0.106 0.055" rpy="0 0 0" />
    <axis xyz="0 1 0" rpy="0 0 0" />
    <dynamics damping="0.0" friction="0.0" />
</joint>
<joint name="wheel_3_axis" type="continuous">
    <parent link="body"/>
    <child link="wheel_3_left"/>
    <origin xyz="-0.08 0.106 0.055" rpy="0 0 0" />
    <axis xyz="0 1 0" rpy="0 0 0" />
    <dynamics damping="0.0" friction="0.0" />
</joint>
<joint name="wheel_4_axis" type="continuous">
    <parent link="body"/>
    <child link="wheel_4_right"/>
    <origin xyz="-0.08 -0.106 0.055" rpy="0 0 0" />
    <axis xyz="0 1 0" rpy="0 0 0" />
    <dynamics damping="0.0" friction="0.0" />
</joint>
</robot>
